Traceback (most recent call last):
  File "/home/mythezone/miniconda3/envs/hf/lib/python3.13/site-packages/gradio/queueing.py", line 625, in process_events
    response = await route_utils.call_process_api(
               ^^^^^^^^^^^^^^^^^^^^^^^^^^^^^^^^^^^
    ...<5 lines>...
    )
    ^
  File "/home/mythezone/miniconda3/envs/hf/lib/python3.13/site-packages/gradio/route_utils.py", line 322, in call_process_api
    output = await app.get_blocks().process_api(
             ^^^^^^^^^^^^^^^^^^^^^^^^^^^^^^^^^^^
    ...<11 lines>...
    )
    ^
  File "/home/mythezone/miniconda3/envs/hf/lib/python3.13/site-packages/gradio/blocks.py", line 2156, in process_api
    data = await self.postprocess_data(block_fn, result["prediction"], state)
           ^^^^^^^^^^^^^^^^^^^^^^^^^^^^^^^^^^^^^^^^^^^^^^^^^^^^^^^^^^^^^^^^^^
  File "/home/mythezone/miniconda3/envs/hf/lib/python3.13/site-packages/gradio/blocks.py", line 1890, in postprocess_data
    self.validate_outputs(block_fn, predictions)  # type: ignore
    ~~~~~~~~~~~~~~~~~~~~~^^^^^^^^^^^^^^^^^^^^^^^
  File "/home/mythezone/miniconda3/envs/hf/lib/python3.13/site-packages/gradio/blocks.py", line 1845, in validate_outputs
                raise ValueError(
    ...<5 lines>...
                )
ValueError: A  function (show_candlestick) didn't return enough output values (needed: 3, returned: 2).
    Output components:
        [textbox, plot, file]
    Output values returned:
        ["没有找到 000001_sh1 在 2024-04-23 的数据", None]
Traceback (most recent call last):
  File "/home/mythezone/miniconda3/envs/hf/lib/python3.13/site-packages/sqlalchemy/engine/base.py", line 1964, in _exec_single_context
    self.dialect.do_execute(
    ~~~~~~~~~~~~~~~~~~~~~~~^
        cursor, str_statement, effective_parameters, context
        ^^^^^^^^^^^^^^^^^^^^^^^^^^^^^^^^^^^^^^^^^^^^^^^^^^^^
    )
    ^
  File "/home/mythezone/miniconda3/envs/hf/lib/python3.13/site-packages/sqlalchemy/engine/default.py", line 945, in do_execute
    cursor.execute(statement, parameters)
    ~~~~~~~~~~~~~~^^^^^^^^^^^^^^^^^^^^^^^
  File "/home/mythezone/miniconda3/envs/hf/lib/python3.13/site-packages/pymysql/cursors.py", line 153, in execute
    result = self._query(query)
  File "/home/mythezone/miniconda3/envs/hf/lib/python3.13/site-packages/pymysql/cursors.py", line 322, in _query
    conn.query(q)
    ~~~~~~~~~~^^^
  File "/home/mythezone/miniconda3/envs/hf/lib/python3.13/site-packages/pymysql/connections.py", line 563, in query
    self._affected_rows = self._read_query_result(unbuffered=unbuffered)
                          ~~~~~~~~~~~~~~~~~~~~~~~^^^^^^^^^^^^^^^^^^^^^^^
  File "/home/mythezone/miniconda3/envs/hf/lib/python3.13/site-packages/pymysql/connections.py", line 825, in _read_query_result
    result.read()
    ~~~~~~~~~~~^^
  File "/home/mythezone/miniconda3/envs/hf/lib/python3.13/site-packages/pymysql/connections.py", line 1199, in read
    first_packet = self.connection._read_packet()
  File "/home/mythezone/miniconda3/envs/hf/lib/python3.13/site-packages/pymysql/connections.py", line 775, in _read_packet
    packet.raise_for_error()
    ~~~~~~~~~~~~~~~~~~~~~~^^
  File "/home/mythezone/miniconda3/envs/hf/lib/python3.13/site-packages/pymysql/protocol.py", line 219, in raise_for_error
    err.raise_mysql_exception(self._data)
    ~~~~~~~~~~~~~~~~~~~~~~~~~^^^^^^^^^^^^
  File "/home/mythezone/miniconda3/envs/hf/lib/python3.13/site-packages/pymysql/err.py", line 150, in raise_mysql_exception
    raise errorclass(errno, errval)
pymysql.err.OperationalError: (1525, "Incorrect DATE value: ''")

The above exception was the direct cause of the following exception:

Traceback (most recent call last):
  File "/home/mythezone/miniconda3/envs/hf/lib/python3.13/site-packages/gradio/queueing.py", line 625, in process_events
    response = await route_utils.call_process_api(
               ^^^^^^^^^^^^^^^^^^^^^^^^^^^^^^^^^^^
    ...<5 lines>...
    )
    ^
  File "/home/mythezone/miniconda3/envs/hf/lib/python3.13/site-packages/gradio/route_utils.py", line 322, in call_process_api
    output = await app.get_blocks().process_api(
             ^^^^^^^^^^^^^^^^^^^^^^^^^^^^^^^^^^^
    ...<11 lines>...
    )
    ^
  File "/home/mythezone/miniconda3/envs/hf/lib/python3.13/site-packages/gradio/blocks.py", line 2146, in process_api
    result = await self.call_function(
             ^^^^^^^^^^^^^^^^^^^^^^^^^
    ...<8 lines>...
    )
    ^
  File "/home/mythezone/miniconda3/envs/hf/lib/python3.13/site-packages/gradio/blocks.py", line 1664, in call_function
    prediction = await anyio.to_thread.run_sync(  # type: ignore
                 ^^^^^^^^^^^^^^^^^^^^^^^^^^^^^^^^^^^^^^^^^^^^^^^
        fn, *processed_input, limiter=self.limiter
        ^^^^^^^^^^^^^^^^^^^^^^^^^^^^^^^^^^^^^^^^^^
    )
    ^
  File "/home/mythezone/miniconda3/envs/hf/lib/python3.13/site-packages/anyio/to_thread.py", line 56, in run_sync
    return await get_async_backend().run_sync_in_worker_thread(
           ^^^^^^^^^^^^^^^^^^^^^^^^^^^^^^^^^^^^^^^^^^^^^^^^^^^^
        func, args, abandon_on_cancel=abandon_on_cancel, limiter=limiter
        ^^^^^^^^^^^^^^^^^^^^^^^^^^^^^^^^^^^^^^^^^^^^^^^^^^^^^^^^^^^^^^^^
    )
    ^
  File "/home/mythezone/miniconda3/envs/hf/lib/python3.13/site-packages/anyio/_backends/_asyncio.py", line 2470, in run_sync_in_worker_thread
    return await future
           ^^^^^^^^^^^^
  File "/home/mythezone/miniconda3/envs/hf/lib/python3.13/site-packages/anyio/_backends/_asyncio.py", line 967, in run
    result = context.run(func, *args)
  File "/home/mythezone/miniconda3/envs/hf/lib/python3.13/site-packages/gradio/utils.py", line 884, in wrapper
    response = f(*args, **kwargs)
  File "/home/mythezone/services/database/fin_bert/web/main.py", line 53, in show_candlestick
    df = pd.read_sql(query, engine, params={"date": date_str}, parse_dates=["datetime"])
  File "/home/mythezone/miniconda3/envs/hf/lib/python3.13/site-packages/pandas/io/sql.py", line 734, in read_sql
    return pandas_sql.read_query(
           ~~~~~~~~~~~~~~~~~~~~~^
        sql,
        ^^^^
    ...<6 lines>...
        dtype=dtype,
        ^^^^^^^^^^^^
    )
    ^
  File "/home/mythezone/miniconda3/envs/hf/lib/python3.13/site-packages/pandas/io/sql.py", line 1836, in read_query
    result = self.execute(sql, params)
  File "/home/mythezone/miniconda3/envs/hf/lib/python3.13/site-packages/pandas/io/sql.py", line 1660, in execute
    return self.con.execute(sql, *args)
           ~~~~~~~~~~~~~~~~^^^^^^^^^^^^
  File "/home/mythezone/miniconda3/envs/hf/lib/python3.13/site-packages/sqlalchemy/engine/base.py", line 1416, in execute
    return meth(
        self,
        distilled_parameters,
        execution_options or NO_OPTIONS,
    )
  File "/home/mythezone/miniconda3/envs/hf/lib/python3.13/site-packages/sqlalchemy/sql/elements.py", line 523, in _execute_on_connection
    return connection._execute_clauseelement(
           ~~~~~~~~~~~~~~~~~~~~~~~~~~~~~~~~~^
        self, distilled_params, execution_options
        ^^^^^^^^^^^^^^^^^^^^^^^^^^^^^^^^^^^^^^^^^
    )
    ^
  File "/home/mythezone/miniconda3/envs/hf/lib/python3.13/site-packages/sqlalchemy/engine/base.py", line 1638, in _execute_clauseelement
    ret = self._execute_context(
        dialect,
    ...<8 lines>...
        cache_hit=cache_hit,
    )
  File "/home/mythezone/miniconda3/envs/hf/lib/python3.13/site-packages/sqlalchemy/engine/base.py", line 1843, in _execute_context
    return self._exec_single_context(
           ~~~~~~~~~~~~~~~~~~~~~~~~~^
        dialect, context, statement, parameters
        ^^^^^^^^^^^^^^^^^^^^^^^^^^^^^^^^^^^^^^^
    )
    ^
  File "/home/mythezone/miniconda3/envs/hf/lib/python3.13/site-packages/sqlalchemy/engine/base.py", line 1983, in _exec_single_context
    self._handle_dbapi_exception(
    ~~~~~~~~~~~~~~~~~~~~~~~~~~~~^
        e, str_statement, effective_parameters, cursor, context
        ^^^^^^^^^^^^^^^^^^^^^^^^^^^^^^^^^^^^^^^^^^^^^^^^^^^^^^^
    )
    ^
  File "/home/mythezone/miniconda3/envs/hf/lib/python3.13/site-packages/sqlalchemy/engine/base.py", line 2352, in _handle_dbapi_exception
    raise sqlalchemy_exception.with_traceback(exc_info[2]) from e
  File "/home/mythezone/miniconda3/envs/hf/lib/python3.13/site-packages/sqlalchemy/engine/base.py", line 1964, in _exec_single_context
    self.dialect.do_execute(
    ~~~~~~~~~~~~~~~~~~~~~~~^
        cursor, str_statement, effective_parameters, context
        ^^^^^^^^^^^^^^^^^^^^^^^^^^^^^^^^^^^^^^^^^^^^^^^^^^^^
    )
    ^
  File "/home/mythezone/miniconda3/envs/hf/lib/python3.13/site-packages/sqlalchemy/engine/default.py", line 945, in do_execute
    cursor.execute(statement, parameters)
    ~~~~~~~~~~~~~~^^^^^^^^^^^^^^^^^^^^^^^
  File "/home/mythezone/miniconda3/envs/hf/lib/python3.13/site-packages/pymysql/cursors.py", line 153, in execute
    result = self._query(query)
  File "/home/mythezone/miniconda3/envs/hf/lib/python3.13/site-packages/pymysql/cursors.py", line 322, in _query
    conn.query(q)
    ~~~~~~~~~~^^^
  File "/home/mythezone/miniconda3/envs/hf/lib/python3.13/site-packages/pymysql/connections.py", line 563, in query
    self._affected_rows = self._read_query_result(unbuffered=unbuffered)
                          ~~~~~~~~~~~~~~~~~~~~~~~^^^^^^^^^^^^^^^^^^^^^^^
  File "/home/mythezone/miniconda3/envs/hf/lib/python3.13/site-packages/pymysql/connections.py", line 825, in _read_query_result
    result.read()
    ~~~~~~~~~~~^^
  File "/home/mythezone/miniconda3/envs/hf/lib/python3.13/site-packages/pymysql/connections.py", line 1199, in read
    first_packet = self.connection._read_packet()
  File "/home/mythezone/miniconda3/envs/hf/lib/python3.13/site-packages/pymysql/connections.py", line 775, in _read_packet
    packet.raise_for_error()
    ~~~~~~~~~~~~~~~~~~~~~~^^
  File "/home/mythezone/miniconda3/envs/hf/lib/python3.13/site-packages/pymysql/protocol.py", line 219, in raise_for_error
    err.raise_mysql_exception(self._data)
    ~~~~~~~~~~~~~~~~~~~~~~~~~^^^^^^^^^^^^
  File "/home/mythezone/miniconda3/envs/hf/lib/python3.13/site-packages/pymysql/err.py", line 150, in raise_mysql_exception
    raise errorclass(errno, errval)
sqlalchemy.exc.OperationalError: (pymysql.err.OperationalError) (1525, "Incorrect DATE value: ''")
[SQL: 
        SELECT * FROM `000001_sh1` 
        WHERE DATE(datetime) = %(date)s 
        ORDER BY datetime ASC
    ]
[parameters: {'date': ''}]
(Background on this error at: https://sqlalche.me/e/20/e3q8)
